Time slot   0
ld_routine
	Loaded a process at input/proc/t9, PID: 1 PRIO: 1
Time slot   1
	CPU 0: Dispatched process  1
liballoc:234
print_pgtbl:
 PGD=00000008a6c25000 P4D=00000008a6c26000 PUD=00000008a6c27000 PMD=00000008a6c28000 PTE=0000000000000001
Time slot   2
	CPU 0: Put process  1 to run queue
	CPU 0: Dispatched process  1
liballoc:234
print_pgtbl:
 PGD=00000008a6c25000 P4D=00000008a6c26000 PUD=00000008a6c27000 PMD=00000008a6c28000 PTE=0000000000000001
 PGD=00000008a6c25000 P4D=00000008a6c26000 PUD=00000008a6c27000 PMD=00000008a6c28000 PTE=0000000000001001
Time slot   3
	CPU 0: Put process  1 to run queue
	CPU 0: Dispatched process  1
Time slot   4
	CPU 0: Put process  1 to run queue
	CPU 0: Dispatched process  1
Time slot   5
	CPU 0: Put process  1 to run queue
	CPU 0: Dispatched process  1
libwrite:535
print_pgtbl:
 PGD=00000008a6c25000 P4D=00000008a6c26000 PUD=00000008a6c27000 PMD=00000008a6c28000 PTE=0000000000000001
 PGD=00000008a6c25000 P4D=00000008a6c26000 PUD=00000008a6c27000 PMD=00000008a6c28000 PTE=0000000000001001
Time slot   6
	CPU 0: Put process  1 to run queue
	CPU 0: Dispatched process  1
libwrite:535
print_pgtbl:
 PGD=00000008a6c25000 P4D=00000008a6c26000 PUD=00000008a6c27000 PMD=00000008a6c28000 PTE=0000000000000001
 PGD=00000008a6c25000 P4D=00000008a6c26000 PUD=00000008a6c27000 PMD=00000008a6c28000 PTE=0000000000001001
Time slot   7
	CPU 0: Put process  1 to run queue
	CPU 0: Dispatched process  1
libwrite:535
print_pgtbl:
 PGD=00000008a6c25000 P4D=00000008a6c26000 PUD=00000008a6c27000 PMD=00000008a6c28000 PTE=0000000000000001
 PGD=00000008a6c25000 P4D=00000008a6c26000 PUD=00000008a6c27000 PMD=00000008a6c28000 PTE=0000000000001001
Time slot   8
	CPU 0: Put process  1 to run queue
	CPU 0: Dispatched process  1
Time slot   9
	CPU 0: Put process  1 to run queue
	CPU 0: Dispatched process  1
Time slot  10
	CPU 0: Put process  1 to run queue
	CPU 0: Dispatched process  1
Time slot  11
	CPU 0: Put process  1 to run queue
	CPU 0: Dispatched process  1
Time slot  12
	CPU 0: Put process  1 to run queue
	CPU 0: Dispatched process  1
libread:470
Time slot  13
	CPU 0: Put process  1 to run queue
	CPU 0: Dispatched process  1
libread:470
Time slot  14
	CPU 0: Processed  1 has finished
	CPU 0 stopped
