Time slot   0
ld_routine
Time slot   1
Time slot   2
	Loaded a process at input/proc/v2, PID: 1 PRIO: 2
Time slot   3
	CPU 1: Dispatched process  1
	Loaded a process at input/proc/v1, PID: 2 PRIO: 0
Time slot   4
	CPU 1: Put process  1 to run queue (pc=1/8)
	CPU 1: Dispatched process  2
	CPU 0: Dispatched process  1
	Loaded a process at input/proc/v2, PID: 3 PRIO: 1
Time slot   5
	CPU 1: Put process  2 to run queue (pc=1/7)
	CPU 1: Dispatched process  2
	CPU 0: Put process  1 to run queue (pc=2/8)
	CPU 0: Dispatched process  3
	Loaded a process at input/proc/v1, PID: 4 PRIO: 2
Time slot   6
	CPU 1: Put process  2 to run queue (pc=2/7)
	CPU 1: Dispatched process  2
	CPU 0: Put process  3 to run queue (pc=1/8)
	CPU 0: Dispatched process  3
	Loaded a process at input/proc/v2, PID: 5 PRIO: 0
Time slot   7
	CPU 1: Put process  2 to run queue (pc=3/7)
	CPU 1: Dispatched process  5
	CPU 0: Put process  3 to run queue (pc=2/8)
	CPU 0: Dispatched process  2
	Loaded a process at input/proc/v1, PID: 6 PRIO: 1
Time slot   8
	CPU 1: Put process  5 to run queue (pc=1/8)
	CPU 1: Dispatched process  5
	CPU 0: Put process  2 to run queue (pc=4/7)
	CPU 0: Dispatched process  2
	Loaded a process at input/proc/v2, PID: 7 PRIO: 2
Time slot   9
	CPU 1: Put process  5 to run queue (pc=2/8)
	CPU 1: Dispatched process  5
	CPU 0: Put process  2 to run queue (pc=5/7)
	CPU 0: Dispatched process  2
	Loaded a process at input/proc/v1, PID: 8 PRIO: 0
Time slot  10
	CPU 1: Put process  5 to run queue (pc=3/8)
	CPU 0: Put process  2 to run queue (pc=6/7)
	CPU 1: Dispatched process  8
	CPU 0: Dispatched process  5
	Loaded a process at input/proc/v2, PID: 9 PRIO: 1
Time slot  11
	CPU 1: Put process  8 to run queue (pc=1/7)
	CPU 1: Dispatched process  2
	CPU 0: Put process  5 to run queue (pc=4/8)
	CPU 0: Dispatched process  8
	Loaded a process at input/proc/v1, PID: 10 PRIO: 2
Time slot  12
	CPU 1: Processed  2 has finished
	CPU 0: Put process  8 to run queue (pc=2/7)
	CPU 0: Dispatched process  5
	CPU 1: Dispatched process  8
Time slot  13
	CPU 0: Put process  5 to run queue (pc=5/8)
	CPU 1: Put process  8 to run queue (pc=3/7)
	CPU 0: Dispatched process  5
	CPU 1: Dispatched process  8
Time slot  14
	CPU 1: Put process  8 to run queue (pc=4/7)
	CPU 1: Dispatched process  8
	CPU 0: Put process  5 to run queue (pc=6/8)
	CPU 0: Dispatched process  5
Time slot  15
	CPU 1: Put process  8 to run queue (pc=5/7)
	CPU 1: Dispatched process  8
	CPU 0: Put process  5 to run queue (pc=7/8)
	CPU 0: Dispatched process  5
Time slot  16
	CPU 1: Put process  8 to run queue (pc=6/7)
	CPU 1: Dispatched process  8
	CPU 0: Processed  5 has finished
	CPU 0: Dispatched process  3
Time slot  17
	CPU 1: Processed  8 has finished
	CPU 0: Put process  3 to run queue (pc=3/8)
	CPU 0: Dispatched process  9
	CPU 1: Dispatched process  6
Time slot  18
	CPU 1: Put process  6 to run queue (pc=1/7)
	CPU 1: Dispatched process  3
	CPU 0: Put process  9 to run queue (pc=1/8)
	CPU 0: Dispatched process  6
Time slot  19
	CPU 1: Put process  3 to run queue (pc=4/8)
	CPU 1: Dispatched process  9
	CPU 0: Put process  6 to run queue (pc=2/7)
	CPU 0: Dispatched process  3
Time slot  20
	CPU 1: Put process  9 to run queue (pc=2/8)
	CPU 1: Dispatched process  6
	CPU 0: Put process  3 to run queue (pc=5/8)
	CPU 0: Dispatched process  9
Time slot  21
	CPU 1: Put process  6 to run queue (pc=3/7)
	CPU 1: Dispatched process  3
	CPU 0: Put process  9 to run queue (pc=3/8)
	CPU 0: Dispatched process  6
Time slot  22
	CPU 1: Put process  3 to run queue (pc=6/8)
	CPU 1: Dispatched process  9
	CPU 0: Put process  6 to run queue (pc=4/7)
	CPU 0: Dispatched process  3
Time slot  23
	CPU 1: Put process  9 to run queue (pc=4/8)
	CPU 0: Put process  3 to run queue (pc=7/8)
	CPU 1: Dispatched process  6
	CPU 0: Dispatched process  9
Time slot  24
	CPU 0: Put process  9 to run queue (pc=5/8)
	CPU 1: Put process  6 to run queue (pc=5/7)
	CPU 0: Dispatched process  3
	CPU 1: Dispatched process  9
Time slot  25
	CPU 1: Put process  9 to run queue (pc=6/8)
	CPU 1: Dispatched process  6
	CPU 0: Processed  3 has finished
	CPU 0: Dispatched process  9
Time slot  26
	CPU 1: Put process  6 to run queue (pc=6/7)
	CPU 1: Dispatched process  6
	CPU 0: Put process  9 to run queue (pc=7/8)
	CPU 0: Dispatched process  9
Time slot  27
	CPU 1: Processed  6 has finished
	CPU 1: Dispatched process  1
	CPU 0: Processed  9 has finished
	CPU 0: Dispatched process  4
Time slot  28
	CPU 1: Put process  1 to run queue (pc=3/8)
	CPU 1: Dispatched process  7
	CPU 0: Put process  4 to run queue (pc=1/7)
	CPU 0: Dispatched process 10
Time slot  29
	CPU 1: Put process  7 to run queue (pc=1/8)
	CPU 0: Put process 10 to run queue (pc=1/7)
	CPU 1: Dispatched process  1
	CPU 0: Dispatched process  4
Time slot  30
	CPU 0: Put process  4 to run queue (pc=2/7)
	CPU 1: Put process  1 to run queue (pc=4/8)
	CPU 0: Dispatched process  7
	CPU 1: Dispatched process 10
Time slot  31
	CPU 1: Put process 10 to run queue (pc=2/7)
	CPU 0: Put process  7 to run queue (pc=2/8)
	CPU 0: Dispatched process  1
	CPU 1: Dispatched process  4
Time slot  32
	CPU 1: Put process  4 to run queue (pc=3/7)
	CPU 1: Dispatched process 10
	CPU 0: Put process  1 to run queue (pc=5/8)
	CPU 0: Dispatched process  7
Time slot  33
	CPU 1: Put process 10 to run queue (pc=3/7)
	CPU 0: Put process  7 to run queue (pc=3/8)
	CPU 1: Dispatched process  4
	CPU 0: Dispatched process  1
Time slot  34
	CPU 1: Put process  4 to run queue (pc=4/7)
	CPU 1: Dispatched process 10
	CPU 0: Put process  1 to run queue (pc=6/8)
	CPU 0: Dispatched process  7
Time slot  35
	CPU 1: Put process 10 to run queue (pc=4/7)
	CPU 1: Dispatched process  4
	CPU 0: Put process  7 to run queue (pc=4/8)
	CPU 0: Dispatched process  1
Time slot  36
	CPU 1: Put process  4 to run queue (pc=5/7)
	CPU 1: Dispatched process 10
	CPU 0: Put process  1 to run queue (pc=7/8)
	CPU 0: Dispatched process  7
Time slot  37
	CPU 1: Put process 10 to run queue (pc=5/7)
	CPU 1: Dispatched process  4
	CPU 0: Put process  7 to run queue (pc=5/8)
	CPU 0: Dispatched process  1
Time slot  38
	CPU 1: Put process  4 to run queue (pc=6/7)
	CPU 1: Dispatched process 10
	CPU 0: Processed  1 has finished
	CPU 0: Dispatched process  7
Time slot  39
	CPU 1: Put process 10 to run queue (pc=6/7)
	CPU 1: Dispatched process  4
	CPU 0: Put process  7 to run queue (pc=6/8)
	CPU 0: Dispatched process 10
Time slot  40
	CPU 1: Processed  4 has finished
	CPU 0: Processed 10 has finished
	CPU 1: Dispatched process  7
	CPU 0 stopped
Time slot  41
	CPU 1: Put process  7 to run queue (pc=7/8)
	CPU 1: Dispatched process  7
Time slot  42
	CPU 1: Processed  7 has finished
	CPU 1 stopped
